Workbook

Sheet !! LICENSE - READ FIRST !!
AA1: License-ID: CN-NIST-CSF-SMB-20260522-001
B2: LICENSE AND TERMS OF USE
B3: NIST CSF 2.0 Small Business Cyber Risk Workplan
B4: Copyright 2026 Cyber Native. All rights reserved. Contact: hello@cybernative.uk
B5: By using, opening, or adapting this workbook you confirm that you have read and agree to the terms below. Commercial use requires a separate license. Contact [EMAIL ADDRESS] for details.
B7: 1. License
B8: Creative Commons BY-NC-SA 4.0 | C8: creativecommons.org/licenses/by-nc-sa/4.0
B9: This Framework (the "Framework") is published by Cyber Native and licensed under the Creative Commons Attribution-NonCommercial-ShareAlike 4.0 International License (CC BY-NC-SA 4.0). By using, adapting, or sharing this Framework you agree to the conditions set out below.
B11: 2. License Conditions
B12: BY - Attribution | C12: Credit must be given to Cyber Native as the originating author. The CC BY-NC-SA 4.0 license identifier and a link to creativecommons.org/licenses/by-nc-sa/4.0 must be retained on all copies and adaptations. Attribution must not suggest that Cyber Native endorses any particular use unless separately agreed in writing.
B13: NC - Non-Commercial | C13: The Framework may not be used for commercial purposes. This includes, without limitation, paid consulting or advisory engagements delivered to third-party clients; embedding the assessment logic or methodology in a commercial software or SaaS product; and use as a primary resource in paid training, workshops, or certification programs. Commercial use requires a separate license from Cyber Native. Contact hello@cybernative.uk for details.
B14: SA - Share-Alike | C14: Adaptations of the Framework are permitted for internal use and internal circulation within a single organization. Internal adaptation and internal circulation do not constitute external distribution and therefore do not trigger the Share-Alike condition. Where an adaptation is shared externally (made available to any party outside the adapting organization) it must be distributed under the same CC BY-NC-SA 4.0 license terms. No additional restrictions may be applied to externally shared adaptations beyond those in this license.
B16: 3. Third-Party Rights and Acknowledgements
B17: This Framework references material published by third-party organizations. Those rights are unaffected by this license. Users of this Framework remain independently bound by the original terms applicable to any such referenced material.
B18: NIST Publications - Public Domain | C18: This Framework references publications of the National Institute of Standards and Technology (NIST), a non-regulatory agency of the United States Department of Commerce. NIST publications are works of the United States federal government and are not subject to copyright protection in the United States under 17 U.S.C. Section 105. They may be used freely without restriction within the United States. International users should verify applicable local rules regarding the use of US federal government publications.
B20: 4. Attribution and Integrity
B21: All copies and adaptations must retain this license notice and credit Cyber Native as the originating author of the Framework. The Framework must not be represented as the original work of any other individual or organization.
B23: 5. No Warranty
B24: The Framework is provided on an "as-is" basis. It does not constitute legal, regulatory, or professional advice. No liability is accepted for decisions made in reliance on its outputs.
B26: Cyber Native | cybernative.uk | Licensed under CC BY-NC-SA 4.0 | NIST CSF 2.0 Small Business Cyber Risk Workplan | 2026

Sheet Cover
AA1: License-ID: CN-NIST-CSF-SMB-20260522-001
B2: CYBER NATIVE
B3: NIST CSF 2.0 Small Business Cyber Risk Workplan
B4: A structured maturity assessment aligned to the NIST Cybersecurity Framework 2.0 and the NIST SP 1300 Small Business Quick-Start Guide
B6: Organization Details
B7: Organization Name
B8: Industry / Sector
B9: Approximate Headcount
B10: Primary Assessor
B11: Program Authority
B12: Assessment Start Date
B13: Assessment Completion Date
B14: Note: the date above drives the Remediation Plan start date automatically. The Remediation Plan opens 14 calendar days after this date.
B16: Document Control
B17: Document Reference | C17: CN-NIST-CSF-SMB-WORKPLAN-v0.001
B18: Version | C18: v0.001
B19: Issue Date
B20: Status | C20: Published
B21: Classification | C21: Confidential
B22: Program Authority
B24: Framework Reference
B25: Primary Framework | C25: NIST Cybersecurity Framework 2.0 (CSF 2.0)
B26: SMB Guide | C26: NIST SP 1300 - Small Business Quick-Start Guide (Feb 2024)
B27: Framework URL | C27: csrc.nist.gov/pubs/sp/1300/final
B28: Assessment Coverage | C28: All 6 CSF 2.0 Functions: Govern, Identify, Protect, Detect, Respond, Recover
B30: Scoring Model - Three-Point Maturity Scale
B31: Each action in the Controls Assessment is scored on a three-point scale. Score entries are selected from a dropdown. The overall maturity rating for each CSF Function and for the full program is calculated automatically.
B32: Implemented (Score 2 / 2) | C32: The action is fully in place. Evidence confirms consistent, documented implementation.
B33: Partial (Score 1 / 2) | C33: The action is in progress or partially implemented. Gaps remain.
B34: Not Started (Score 0 / 2) | C34: The action has not been started. No evidence of implementation.
B35: Not Assessed | C35: The row has not yet been reviewed by the assessor.
B37: How to Use This Workbook
B38: Step 1 - Complete Business Context | C38: Open the Business and Technology Context sheet and complete all fields before beginning the assessment. This grounds all subsequent judgements in your specific operating environment.
B39: Step 2 - Work Through Controls Assessment | C39: For each row in the Controls Assessment sheet, review the action description and evidence guidance. Select a score from the dropdown in column K and record your evidence in column P.
B40: Step 3 - Review the Dashboard | C40: The Dashboard updates automatically as scores are entered. Use it to identify which CSF Functions and CSF Tiers have the greatest concentration of gaps.
B41: Step 4 - Prioritize Using Remediation Plan | C41: The Remediation Plan is pre-loaded with all assessment actions. Items that are Partial or Not Started remain visible as remediation tasks. Set owners and target dates to build your action plan.
B42: Step 5 - Complete Supporting Registers | C42: Use the RAID Log and Risk Register to capture program risks and findings in enterprise risk language. The Stakeholder Register supports engagement planning across responsible teams.
B43: Step 6 - Re-assess Periodically | C43: Update scores as controls are implemented. The Dashboard and Remediation Plan will reflect progress in real time. Version the workbook on each re-assessment cycle.
B45: Cyber Native | cybernative.uk | Licensed under CC BY-NC-SA 4.0 | NIST CSF 2.0 Small Business Cyber Risk Workplan | 2026

Sheet Instructions
AA1: License-ID: CN-NIST-CSF-SMB-20260522-001
B2: INSTRUCTIONS
B3: NIST CSF 2.0 Small Business Cyber Risk Workplan
B4: Read this sheet before beginning the assessment. It explains each column in the Controls Assessment, the scoring model, and how to navigate the workbook.
B6: Purpose of This Workplan
B7: This workplan provides a structured, evidence-based assessment of cybersecurity practice against the NIST Cybersecurity Framework 2.0 (CSF 2.0), oriented specifically for small and medium-sized businesses (SMBs). It covers all six CSF 2.0 Functions: Govern, Identify, Protect, Detect, Respond, and Recover. Assessment actions are drawn from NIST SP 1300, the NIST Small Business Quick-Start Guide (February 2024), mapped to their corresponding CSF 2.0 subcategory codes. Metric definitions reference the full CSF 2.0 core framework (NIST CSWP 29).
B9: Workbook Structure and Navigation
B10: !! LICENSE - READ FIRST !! | C10: License terms and conditions of use. Read before distributing.
B11: Cover | C11: Organization details, document control, framework reference, and scoring key.
B12: Instructions | C12: This sheet. Column guide, scoring logic, and navigation reference.
B13: Business and Technology Context | C13: Pre-assessment scoping sheet. Complete before opening Controls Assessment.
B14: Controls Assessment | C14: Primary working sheet. All 22 columns across all 6 CSF Functions.
B15: Dashboard | C15: Six-panel visual summary. Updates automatically as scores are entered.
B16: Assessment Detail Capture | C16: Expanded evidence documentation. One row per evidence item per metric.
B17: Remediation Plan | C17: Pre-loaded action plan. Failing items appear as remediation tasks automatically.
B18: RAID Log | C18: Program-level risks, assumptions, issues, and dependencies.
B19: Risk Register | C19: Enterprise risks linked to assessment findings.
B20: Stakeholder Register | C20: Key contacts and engagement tracking.
B21: Remediation Index | C21: Working sheet driving Remediation Plan visibility. Do not edit directly.
B23: Column Type Legend
B24: Pre-populated | C24: Content is sourced from NIST CSF 2.0 and SP 1300. Do not edit.
B25: Assessor Input | C25: Assessor completes these fields during the assessment. Blue text on white or shaded background.
B26: Auto-Calculated | C26: Formula-driven. Updates automatically. Do not edit.
B28: Controls Assessment - Column Reference Guide (22 Columns)
B29: Col | C29: Field Name | D29: Description
B30: A | C30: CSF Function | D30: Primary filter anchor. One of six CSF 2.0 Functions: Govern, Identify, Protect, Detect, Respond, Recover. AutoFilter is enabled on all 22 columns.
B31: B | C31: Category | D31: CSF 2.0 Category code and name. For example: GV.OC - Organizational Context. Each Function contains between two and five Categories.
B32: C | C32: Subcategory ID | D32: CSF 2.0 Subcategory reference code. For example: GV.OC-01. This is the primary cross-reference to the full CSF 2.0 core framework (NIST CSWP 29).
B33: D | C33: Subcategory Title | D33: Full subcategory outcome statement as published in CSF 2.0. Reproduced verbatim from the authoritative source.
B34: E | C34: CSF Tier Applicability | D34: Indicates the CSF Tier at which this action becomes expected practice: Tier 1 (foundational), Tier 2 (risk-informed), or Tier 3 (repeatable). Tier 4 actions are noted but not separately scored at SMB level.
B35: F | C35: Metric Reference | D35: Unique identifier for this metric row. Format: [Subcategory ID]-M[n]. For example: GV.OC-01-M1. Use this reference in the Assessment Detail Capture sheet and in the Risk Register Source Metric field.
B36: G | C36: Metric Name | D36: Short descriptive name for the metric. Plain language aligned to the SMB audience.
B37: H | C37: Assessment Question | D37: Plain-language question the assessor should answer when reviewing evidence. Derived from SP 1300 actions to consider.
B38: I | C38: Evidence Required | D38: Specific evidence types that would demonstrate implementation. Adapted to the US SMB operating context.
B39: J | C39: Pass Condition | D39: Explicit statement of what constitutes a score of 2 (Implemented) for this metric. Assessors should refer to this field when determining score entries.
B40: K | C40: Assessed Value | D40: Assessor input. Select from dropdown: Not Started / Partial / Implemented. Stored numerically: Not Started = 0, Partial = 1, Implemented = 2. Blue text on shaded background.
... B51: V | C51: Reviewed By | D51: Name of the reviewer or peer reviewer who validated this assessment entry.
B53: Scoring Logic
B54: Each row in the Controls Assessment uses the three-point maturity scale. The assessor selects a value from the dropdown in column K. The Calculated Score (column M) is derived as K divided by L (denominator fixed at 2). The Pass / Partial / Fail status in column O is driven by the calculated score against the pass threshold of 1.0 (column N).
B55: Selection | C55: Col K
...

Sheet Business and Technology Context
AA1: License-ID: CN-NIST-CSF-SMB-20260522-001
B2: BUSINESS AND TECHNOLOGY CONTEXT
B3: NIST CSF 2.0 Small Business Cyber Risk Workplan
B4: Complete all sections below before opening the Controls Assessment. This context shapes scoring judgements and evidence priorities throughout the assessment.
B6: 1. Business Profile
B7: Field | C7: Your Response | D7: Guidance
B8: Legal Business Name | D8: Full legal entity name as registered with your state.
B9: Trading Name (if different) | D9: Name used in day-to-day operations if different from legal name.
B10: Primary Business Activity | D10: Brief description of what the business does.
B11: Industry Sector | D11: Select the closest match: Healthcare / Financial Services / Retail / Manufacturing / Professional Services / Technology / Hospitality / Other.
B12: Business Location(s) | D12: List all US states (and any international locations) where the business operates.
B13: Number of Employees | D13: Full-time equivalent headcount across all locations.
B14: Annual Revenue Band | D14: Select: Under $1M / $1M-$10M / $10M-$50M / $50M-$250M. Used to contextualise proportionality of controls.
B15: Years in Operation
B17: 2. Technology Environment
B18: Field | C18: Your Response | D18: Guidance
B19: Primary Infrastructure Model | D19: Select: Cloud-first / Primarily on-premise / Hybrid. Cloud-first means the majority of workloads run in a public cloud platform.
B20: Primary Cloud Platform(s) | D20: List the cloud platforms in use: AWS, Microsoft Azure, Google Cloud, Microsoft 365, Google Workspace, other SaaS platforms.
B21: On-Premise Server Count | D21: Approximate number of physical or virtual servers hosted in your own facilities.
B22: Approximate Device Count | D22: Total count of laptops, desktops, and mobile devices used for business purposes.
B23: Operating Systems in Use | D23: List primary operating systems: Windows, macOS, Linux, iOS, Android.
B24: Remote Working Posture | D24: Select: Fully remote / Predominantly remote / Hybrid / Predominantly on-site. Note the proportion of employees working remotely.
B25: Software Development Activity | D25: Does the organization develop software internally or for clients? Yes / No. If yes, note the development stack and deployment model.
B26: Operational Technology (OT) or IoT Devices | D26: Does the organization use industrial control systems, SCADA, or IoT devices connected to the business network? Yes / No. If yes, describe.
B28: 3. Network and Connectivity
B29: Field | C29: Your Response | D29: Guidance
B30: Internet Service Provider(s) | D30: List ISPs providing connectivity to business locations.
B31: Number of Internet-Facing Systems | D31: Count of servers, services, or applications accessible from the public internet.
B32: Wireless Networks | D32: Describe wireless network segmentation: corporate, guest, and IoT networks.
B33: VPN or Remote Access Solution | D33: Solution in use for remote employee access to corporate resources, if any.
B34: Third-Party Network Access | D34: Do any third parties (vendors, managed service providers, or contractors) have direct network access to your systems? Yes / No. If yes, list.
B36: 4. Data and Information Assets
B37: Field | C37: Your Response | D37: Guidance
B38: Customer Personal Data | D38: Does the organization collect, store, or process personal data belonging to customers? Yes / No. If yes, approximate record count.
B39: Employee Personal Data | D39: Describe the categories of employee personal data held (payroll, SSN, health, etc.).
B40: Payment Card Data | D40: Does the organization process, store, or transmit payment card data? Yes / No. If yes, note the cardholder data environment scope.
B41: Protected Health Information (PHI) | D41: Does the organization create, receive, maintain, or transmit PHI covered by HIPAA? Yes / No. If yes, describe the data flows.
B42: Proprietary or Trade Secret Information | D42: Does the organization hold intellectual property, trade secrets, or confidential business information that would cause significant harm if disclosed?
B43: Federal Contract Information (FCI) or Controlled Unclassified Information (CUI) | D43: Does the organization work on US federal contracts requiring DFARS or CMMC compliance? Yes / No. If yes, describe the scope.
B45: 5. Regulatory and Contractual Obligations
...

Sheet Controls Assessment
A1: CSF Function | B1: Category | C1: Subcategory ID | D1: Subcategory Title | E1: CSF Tier Applicability | F1: Metric Reference | G1: Metric Name | H1: Assessment Question | I1: Evidence Required | J1: Pass Condition | K1: Assessed Value | L1: Denominator | M1: Calculated Score (%) | N1: Pass Threshold | O1: Pass / Partial / Fail | P1: Evidence Collected | Q1: Suggested Evidence Artifacts | R1: Responsible Function or Team | S1: Key Contact Name | T1: Assessor Notes | U1: Assessment Date | V1: Reviewed By | AA1: License-ID: CN-NIST-CSF-SMB-20260522-001
A2: Govern | B2: GV.OC - Organizational Context | C2: GV.OC-01 | D2: The organizational mission is understood and informs cybersecurity risk management | E2: Tier 1 | F2: GV.OC-01-M1 | G2: Mission and Cyber Risk Alignment | H2: Has the business identified how cybersecurity incidents could disrupt its mission? Has leadership discussed cyber risks in the context of mission-critical operations? | I2: Business mission statement. Evidence that cyber risks have been assessed against business objectives: meeting notes, risk register entries, or strategy documents. | J2: Score 2 (Implemented): A documented link between the business mission and cybersecurity risks exists and has been reviewed by leadership within the past 12 months. | L2: 2 | M2: =IF(K2="","",IF(K2="Implemented",1,IF(K2="Partial",0.5,0))) | N2: 1 | O2: =IF(K2="","Not Assessed",IF(M2>=N2,"PASS",IF(M2>0,"PARTIAL","FAIL"))) -> Not Assessed | Q2: Business mission statement. Strategic plan. Risk register. Leadership meeting notes referencing cybersecurity. | R2: Leadership and Ownership
A3: Govern | B3: GV.OC - Organizational Context | C3: GV.OC-03 | D3: Legal, regulatory, and contractual requirements regarding cybersecurity are understood and managed | E3: Tier 1 | F3: GV.OC-03-M1 | G3: Legal and Regulatory Requirements | H3: Has the business identified all applicable cybersecurity-related legal, regulatory, and contractual obligations? Are these documented, reviewed, and assigned to an owner? | I3: Documented list of applicable requirements with review date and named owner. Examples: HIPAA BAA, PCI DSS SAQ, state breach notification obligations, DFARS clauses. | J3: Score 2 (Implemented): A current register of legal, regulatory, and contractual cybersecurity obligations exists, reviewed within the past 12 months, and assigned to a named owner. | L3: 2 | M3: =IF(K3="","",IF(K3="Implemented",1,IF(K3="Partial",0.5,0))) | N3: 1 | O3: =IF(K3="","Not Assessed",IF(M3>=N3,"PASS",IF(M3>0,"PARTIAL","FAIL"))) -> Not Assessed | Q3: Compliance register. Contracts with cybersecurity clauses. Insurance policy requirements. Regulatory correspondence. | R3: Legal and Compliance
A4: Govern | B4: GV.RR - Roles, Responsibilities, and Authorities | C4: GV.RR-02 | D4: Roles, responsibilities, and authorities related to cybersecurity risk management are established, communicated, understood, and enforced | E4: Tier 2 | F4: GV.RR-02-M1 | G4: Cybersecurity Roles and Responsibilities | H4: Is there a named individual responsible for developing and executing the cybersecurity strategy? Are cybersecurity responsibilities documented in job descriptions or role assignments? | I4: Role assignment documentation. Org chart showing cybersecurity responsibility. Job description referencing cybersecurity duties. Evidence of communication to relevant staff. | J4: Score 2 (Implemented): A named individual or designated role is formally assigned cybersecurity responsibility. The assignment is documented and communicated to leadership and relevant staff. | L4: 2 | M4: =IF(K4="","",IF(K4="Implemented",1,IF(K4="Partial",0.5,0))) | N4: 1 | O4: =IF(K4="","Not Assessed",IF(M4>=N4,"PASS",IF(M4>0,"PARTIAL","FAIL"))) -> Not Assessed | Q4: Org chart. Job description. Role assignment letter or policy section. Staff communication confirming role awareness. | R4: Leadership and Ownership
A5: Govern | B5: GV.OC - Organizational Context | C5: GV.OC-04 | D5: Critical objectives, capabilities, and services that external stakeholders depend on or expect from the organization are understood and communicated | E5: Tier 1 | F5: GV.OC-04-M1 | G5: Critical Asset Impact Assessment | H5: Has the business assessed the impact of a total or partial loss of critical assets and operations? Are the most critical assets and services identified and recovery prioritized? | I5: Business impact analysis (BIA) or equivalent documentation. Asset criticality register. Records of leadership discussion of critical service dependencies. | J5: Score 2 (Implemented): A documented assessment of business impact from loss of critical assets exists, identifies the most critical systems and services, and has been reviewed by leadership within the past 12 months. | L5: 2 | M5: =IF(K5="","",IF(K5="Implemented",1,IF(K5="Partial",0.5,0))) | N5: 1 | O5: =IF(K5="","Not Assessed",IF(M5>=N5,"PASS",IF(M5>0,"PARTIAL","FAIL"))) -> Not Assessed | Q5: Business impact analysis. Critical asset list. Service dependency map. Recovery priority documentation. | R5: Leadership and Ownership
A6: Govern | B6: GV.RM - Risk Management Strategy | C6: GV.RM-04 | D6: Strategic direction describing appropriate risk response options is established and communicated | E6: Tier 2 | F6: GV.RM-04-M1 | G6: Cyber Insurance Evaluation | H6: Has the business assessed whether cyber insurance is appropriate for its risk profile? If a policy is in place, does coverage align with identified exposures? If not, has the decision been documented? | I6: Cyber insurance policy or broker correspondence. Evidence of coverage review against risk profile. Documented decision if no policy is held. | J6: Score 2 (Implemented): The business has formally assessed cyber insurance appropriateness. Either a policy is in place and aligned to identified exposures, or a documented decision explains why no policy is held. | L6: 2 | M6: =IF(K6="","",IF(K6="Implemented",1,IF(K6="Partial",0.5,0))) | N6: 1 | O6: =IF(K6="","Not Assessed",IF(M6>=N6,"PASS",IF(M6>0,"PARTIAL","FAIL"))) -> Not Assessed | Q6: Cyber insurance certificate of coverage. Insurance broker assessment. Risk committee or management decision record. | R6: Leadership and Ownership
A7: Govern | B7: GV.SC - Cybersecurity Supply Chain Risk Management | C7: GV.SC-06 | D7: Planning and due diligence are performed to reduce risks before entering into formal supplier or other third-party relationships | E7: Tier 2 | F7: GV.SC-06-M1 | G7: Supplier Cyber Risk Due Diligence | H7: Does the business assess cybersecurity risks of suppliers and third parties before entering formal relationships? Are security requirements included in vendor contracts or onboarding processes? | I7: Supplier assessment questionnaire or security review process. Vendor contracts referencing security requirements. Evidence that assessments are performed before relationship commencement. | J7: Score 2 (Implemented): A documented process for assessing supplier cybersecurity risks exists. Security requirements are included in contracts. Evidence of recent assessments is available. | L7: 2 | M7: =IF(K7="","",IF(K7="Implemented",1,IF(K7="Partial",0.5,0))) | N7: 1 | O7: =IF(K7="","Not Assessed",IF(M7>=N7,"PASS",IF(M7>0,"PARTIAL","FAIL"))) -> Not Assessed | Q7: Supplier security questionnaire. Vendor contract with security clauses. Third-party risk register. Onboarding checklist. | R7: Procurement and Vendor Management
A8: Govern | B8: GV.RM - Risk Management Strategy | C8: GV.RM-03 | D8: Cybersecurity risk management activities and outcomes are included in enterprise risk management processes | E8: Tier 2 | F8: GV.RM-03-M1 | G8: Enterprise Risk Integration | H8: Are cybersecurity risks managed alongside other business risks in a consistent process? Are cyber risk items visible in the business risk register or equivalent governance mechanism? | I8: Enterprise risk register showing cybersecurity entries. Evidence of regular review. Risk reporting to leadership that includes cyber items. | J8: Score 2 (Implemented): Cybersecurity risks appear in the business risk register. Risk reviews occur at regular intervals. Cyber risk reporting reaches leadership. | L8: 2 | M8: =IF(K8="","",IF(K8="Implemented",1,IF(K8="Partial",0.5,0))) | N8: 1 | O8: =IF(K8="","Not Assessed",IF(M8>=N8,"PASS",IF(M8>0,"PARTIAL","FAIL"))) -> Not Assessed | Q8: Risk register with cyber risk entries. Board or management risk report. Risk committee meeting notes. | R8: Risk Management
A9: Govern | B9: GV.RR - Roles, Responsibilities, and Authorities | C9: GV.RR-01 | D9: Organizational leadership is responsible and accountable for cybersecurity risk and fosters a culture that is risk-aware, ethical, and continually improving | E9: Tier 2 | F9: GV.RR-01-M1 | G9: Leadership Cybersecurity Culture | H9: Has leadership explicitly communicated support for a risk-aware cybersecurity culture? Is there visible leadership commitment to security improvement and ethical information handling? | I9: Leadership communications referencing cybersecurity. Evidence of leadership participation in security reviews or training. Acceptable use policy signed by leadership. | J9: Score 2 (Implemented): Leadership has made documented communications supporting a cybersecurity-aware culture. Evidence of ongoing leadership commitment exists from within the past 12 months. | L9: 2 | M9: =IF(K9="","",IF(K9="Implemented",1,IF(K9="Partial",0.5,0))) | N9: 1 | O9: =IF(K9="","Not Assessed",IF(M9>=N9,"PASS",IF(M9>0,"PARTIAL","FAIL"))) -> Not Assessed | Q9: CEO or leadership communication on cybersecurity. Acceptable use policy with leadership sign-off. Security awareness program records. | R9: Leadership and Ownership
A10: Govern | B10: GV.PO - Policy | C10: GV.PO-01 | D10: Policy for managing cybersecurity risks is established based on organizational context, strategy, and priorities and is communicated and enforced | E10: Tier 2 | F10: GV.PO-01-M1 | G10: Cybersecurity Policy | H10: Does the business have a documented cybersecurity policy communicated to all relevant staff? Is the policy actively enforced and reviewed on a regular basis? | I10: Cybersecurity policy document with version date. Evidence of distribution to staff. Evidence of policy enforcement. | J10: Score 2 (Implemented): A documented cybersecurity policy exists, has been distributed to all relevant staff, is actively enforced, and has been reviewed within the past 12 months. | L10: 2 | M10: =IF(K10="","",IF(K10="Implemented",1,IF(K10="Partial",0.5,0))) | N10: 1 | O10: =IF(K10="","Not Assessed",IF(M10>=N10,"PASS",IF(M10>0,"PARTIAL","FAIL"))) -> Not Assessed | Q10: Cybersecurity or information security policy. Staff acknowledgement records. Policy review log. Acceptable use policy. | R10: Leadership and Ownership
A11: Identify | B11: ID.AM - Asset Management | C11: ID.AM-01, ID.AM-02, ID.AM-04 | D11: Inventories of hardware, software, services, and systems managed by the organization are maintained | E11: Tier 1 | F11: ID.AM-01-M1 | G11: Asset Inventory | H11: Does the business maintain an up-to-date inventory of all hardware, software, systems, and services it relies on? Is the inventory reviewed and updated when assets change? | I11: Asset inventory document, spreadsheet, or IT management tool output. Evidence the inventory was reviewed or updated within the past six months. | J11: Score 2 (Implemented): A current, documented inventory of all key hardware, software, and services exists. Updated within the past six months and covers all primary business systems. | L11: 2 | M11: =IF(K11="","",IF(K11="Implemented",1,IF(K11="Partial",0.5,0))) | N11: 1 | O11: =IF(K11="","Not Assessed",IF(M11>=N11,"PASS",IF(M11>0,"PARTIAL","FAIL"))) -> Not Assessed | Q11: Hardware register. Software license inventory. Cloud service subscription list. IT asset management tool export. Network scan output. | R11: IT Operations
A12: Identify | B12: ID.RA - Risk Assessment | C12: ID.RA-01 | D12: Vulnerabilities in assets are identified, validated, and recorded | E12: Tier 1 | F12: ID.RA-01-M1 | G12: Vulnerability Identification | H12: Does the business have a process for identifying vulnerabilities in its assets? Have key assets been assessed recently? Are identified vulnerabilities recorded and tracked to remediation? | I12: Vulnerability scan reports or assessment output. Vulnerability register or remediation log. Evidence of recent assessment activity. | J12: Score 2 (Implemented): A documented vulnerability identification process exists. Key assets have been scanned or assessed within the past 12 months. Vulnerabilities are tracked to remediation in a register. | L12: 2 | M12: =IF(K12="","",IF(K12="Implemented",1,IF(K12="Partial",0.5,0))) | N12: 1 | O12: =IF(K12="","Not Assessed",IF(M12>=N12,"PASS",IF(M12>0,"PARTIAL","FAIL"))) -> Not Assessed | Q12: Vulnerability scanner output. Penetration test report. Vulnerability register. Patch management records. | R12: IT Operations
A13: Identify | B13: ID.IM - Improvement | C13: ID.IM-01 | D13: Improvements are identified from evaluations | E13: Tier 2 | F13: ID.IM-01-M1 | G13: Cybersecurity Program Effectiveness | H13: Does the business assess the effectiveness of its cybersecurity program and identify areas requiring improvement? Are improvement actions tracked and completed? | I13: Assessment results or self-evaluation documentation. Improvement action log. Evidence of changes made to security controls or processes based on evaluation outcomes. | J13: Score 2 (Implemented): A documented process for evaluating cybersecurity program effectiveness exists. Improvement areas are identified, recorded, and tracked to completion. | L13: 2 | M13: =IF(K13="","",IF(K13="Implemented",1,IF(K13="Partial",0.5,0))) | N13: 1 | O13: =IF(K13="","Not Assessed",IF(M13>=N13,"PASS",IF(M13>0,"PARTIAL","FAIL"))) -> Not Assessed | Q13: Security program review documentation. Audit findings and responses. Improvement action register. Prior assessment results with follow-up evidence. | R13: Risk Management
... A39: Recover | B39: RC.RP - Incident Recovery Plan Execution | C39: RC.RP-06 | D39: The end of incident recovery is declared based on criteria and stakeholder communication regarding incident recovery is executed | E39: Tier 3 | F39: RC.RP-06-M2 | G39: Incident Closure and Resumption Declaration | H39: Does the business have documented criteria for declaring the end of an incident and resumption of normal operations? Is there a formal sign-off process for incident closure? | I39: Incident closure criteria documentation. Evidence of a formal closure declaration from a prior incident or exercise. Sign-off process or approval record. | J39: Score 2 (Implemented): Documented criteria for declaring incident closure exist. A formal sign-off process is in place. Evidence of application in at least one real or simulated incident is available. | L39: 2 | M39: =IF(K39="","",IF(K39="Implemented",1,IF(K39="Partial",0.5,0))) | N39: 1 | O39: =IF(K39="","Not Assessed",IF(M39>=N39,"PASS",IF(M39>0,"PARTIAL","FAIL"))) -> Not Assessed | Q39: Incident closure criteria document. Incident ticket showing closure sign-off. After-action report confirming resumption of normal operations. | R39: Leadership and Ownership

Sheet Dashboard
AA1: License-ID: CN-NIST-CSF-SMB-20260522-001
B2: ASSESSMENT DASHBOARD
B3: NIST CSF 2.0 Small Business Cyber Risk Workplan
B4: All panels update automatically as scores are entered in the Controls Assessment sheet.
B6: Panel 1 Assessment Readiness Summary
B7: Status | C7: Count | D7: % of Total | E7: Cumulative
B8: Implemented | C8: =COUNTIF('Controls Assessment'!K2:K100,"Implemented") -> 0 | D8: =IFERROR(COUNTIF('Controls Assessment'!K2:K100,"Implemented")/COUNTA('Controls Assessment'!F2:F100),0) -> 0 | E8: =IFERROR(COUNTIF('Controls Assessment'!K2:K100,"Implemented")/COUNTA('Controls Assessment'!F2:F100),0) -> 0
B9: Partial | C9: =COUNTIF('Controls Assessment'!K2:K100,"Partial") -> 0 | D9: =IFERROR(COUNTIF('Controls Assessment'!K2:K100,"Partial")/COUNTA('Controls Assessment'!F2:F100),0) -> 0 | E9: =IFERROR((COUNTIF('Controls Assessment'!K2:K100,"Implemented")+COUNTIF('Controls Assessment'!K2:K100,"Partial"))/COUNTA('Controls Assessment'!F2:F100),0) -> 0
B10: Not Started | C10: =COUNTIF('Controls Assessment'!K2:K100,"Not Started") -> 0 | D10: =IFERROR(COUNTIF('Controls Assessment'!K2:K100,"Not Started")/COUNTA('Controls Assessment'!F2:F100),0) -> 0 | E10: =IFERROR((COUNTIF('Controls Assessment'!K2:K100,"Implemented")+COUNTIF('Controls Assessment'!K2:K100,"Partial")+COUNTIF('Controls Assessment'!K2:K100,"Not Started"))/COUNTA('Controls Assessment'!F2:F100),0) -> 0
B11: Not Assessed | C11: =COUNTA('Controls Assessment'!F2:F100)-COUNTA('Controls Assessment'!K2:K100) -> 38 | D11: =IFERROR((COUNTA('Controls Assessment'!F2:F100)-COUNTA('Controls Assessment'!K2:K100))/COUNTA('Controls Assessment'!F2:F100),0) -> 1
B12: Total | C12: =COUNTA('Controls Assessment'!F2:F100) -> 38 | D12: =COUNTA('Controls Assessment'!K2:K100)/COUNTA('Controls Assessment'!F2:F100) -> 0
B14: Panel 2 Function Pass Rate
B15: CSF Function | C15: Total | D15: PASS | E15: PARTIAL / FAIL
B16: Govern | C16: =COUNTIF('Controls Assessment'!A2:A100,"Govern") -> 9 | D16: =COUNTIFS('Controls Assessment'!A2:A100,"Govern",'Controls Assessment'!O2:O100,"PASS") -> 0 | E16: =COUNTIFS('Controls Assessment'!A2:A100,"Govern",'Controls Assessment'!O2:O100,"PARTIAL")+COUNTIFS('Controls Assessment'!A2:A100,"Govern",'Controls Assessment'!O2:O100,"FAIL") -> 0
B17: Identify | C17: =COUNTIF('Controls Assessment'!A2:A100,"Identify") -> 6 | D17: =COUNTIFS('Controls Assessment'!A2:A100,"Identify",'Controls Assessment'!O2:O100,"PASS") -> 0 | E17: =COUNTIFS('Controls Assessment'!A2:A100,"Identify",'Controls Assessment'!O2:O100,"PARTIAL")+COUNTIFS('Controls Assessment'!A2:A100,"Identify",'Controls Assessment'!O2:O100,"FAIL") -> 0
B18: Protect | C18: =COUNTIF('Controls Assessment'!A2:A100,"Protect") -> 7 | D18: =COUNTIFS('Controls Assessment'!A2:A100,"Protect",'Controls Assessment'!O2:O100,"PASS") -> 0 | E18: =COUNTIFS('Controls Assessment'!A2:A100,"Protect",'Controls Assessment'!O2:O100,"PARTIAL")+COUNTIFS('Controls Assessment'!A2:A100,"Protect",'Controls Assessment'!O2:O100,"FAIL") -> 0
B19: Detect | C19: =COUNTIF('Controls Assessment'!A2:A100,"Detect") -> 5 | D19: =COUNTIFS('Controls Assessment'!A2:A100,"Detect",'Controls Assessment'!O2:O100,"PASS") -> 0 | E19: =COUNTIFS('Controls Assessment'!A2:A100,"Detect",'Controls Assessment'!O2:O100,"PARTIAL")+COUNTIFS('Controls Assessment'!A2:A100,"Detect",'Controls Assessment'!O2:O100,"FAIL") -> 0
B20: Respond | C20: =COUNTIF('Controls Assessment'!A2:A100,"Respond") -> 5 | D20: =COUNTIFS('Controls Assessment'!A2:A100,"Respond",'Controls Assessment'!O2:O100,"PASS") -> 0 | E20: =COUNTIFS('Controls Assessment'!A2:A100,"Respond",'Controls Assessment'!O2:O100,"PARTIAL")+COUNTIFS('Controls Assessment'!A2:A100,"Respond",'Controls Assessment'!O2:O100,"FAIL") -> 0
B21: Recover | C21: =COUNTIF('Controls Assessment'!A2:A100,"Recover") -> 6 | D21: =COUNTIFS('Controls Assessment'!A2:A100,"Recover",'Controls Assessment'!O2:O100,"PASS") -> 0 | E21: =COUNTIFS('Controls Assessment'!A2:A100,"Recover",'Controls Assessment'!O2:O100,"PARTIAL")+COUNTIFS('Controls Assessment'!A2:A100,"Recover",'Controls Assessment'!O2:O100,"FAIL") -> 0
B22: All Functions | C22: =COUNTA('Controls Assessment'!F2:F100) -> 38 | D22: =COUNTIF('Controls Assessment'!O2:O100,"PASS") -> 0 | E22: =COUNTIF('Controls Assessment'!O2:O100,"PARTIAL")+COUNTIF('Controls Assessment'!O2:O100,"FAIL") -> 0
B24: Panel 3 Evidence Completeness Tracker
B25: Stage | C25: Completed | D25: Remaining | E25: % Complete
B26: Stage 1 - Assessed (Col K scored) | C26: =COUNTA('Controls Assessment'!K2:K100) -> 0 | D26: =COUNTA('Controls Assessment'!F2:F100)-COUNTA('Controls Assessment'!K2:K100) -> 38 | E26: =IFERROR(COUNTA('Controls Assessment'!K2:K100)/COUNTA('Controls Assessment'!F2:F100),0) -> 0
B27: Stage 2 - Evidence Collected (Col P) | C27: =COUNTA('Controls Assessment'!P2:P100) -> 0 | D27: =COUNTA('Controls Assessment'!F2:F100)-COUNTA('Controls Assessment'!P2:P100) -> 38 | E27: =IFERROR(COUNTA('Controls Assessment'!P2:P100)/COUNTA('Controls Assessment'!F2:F100),0) -> 0
B28: Stage 3 - Reviewed and Signed Off (Col V) | C28: =COUNTA('Controls Assessment'!V2:V100) -> 0 | D28: =COUNTA('Controls Assessment'!F2:F100)-COUNTA('Controls Assessment'!V2:V100) -> 38 | E28: =IFERROR(COUNTA('Controls Assessment'!V2:V100)/COUNTA('Controls Assessment'!F2:F100),0) -> 0
B30: Panel 4 Key Contact Coverage
B31: Metric | C31: Value | D31: % Coverage
B32: Metrics with Named Contact | C32: =COUNTA('Controls Assessment'!S2:S100) -> 0 | D32: =IFERROR(COUNTA('Controls Assessment'!S2:S100)/COUNTA('Controls Assessment'!F2:F100),0) -> 0
B33: Metrics without Named Contact | C33: =COUNTA('Controls Assessment'!F2:F100)-COUNTA('Controls Assessment'!S2:S100) -> 38
B34: Total Metrics | C34: =COUNTA('Controls Assessment'!F2:F100) -> 38
B36: Panel 5 Assessment Burden by Responsible Team
B37: Responsible Team | C37: Metric Count | D37: % of Total
B38: IT Operations | C38: =COUNTIF('Controls Assessment'!R2:R100,"IT Operations") -> 18 | D38: =IFERROR(COUNTIF('Controls Assessment'!R2:R100,"IT Operations")/COUNTA('Controls Assessment'!F2:F100),0) -> 0.47368421
B39: Leadership and Ownership | C39: =COUNTIF('Controls Assessment'!R2:R100,"Leadership and Ownership") -> 11 | D39: =IFERROR(COUNTIF('Controls Assessment'!R2:R100,"Leadership and Ownership")/COUNTA('Controls Assessment'!F2:F100),0) -> 0.28947368
B40: Legal and Compliance | C40: =COUNTIF('Controls Assessment'!R2:R100,"Legal and Compliance") -> 2 | D40: =IFERROR(COUNTIF('Controls Assessment'!R2:R100,"Legal and Compliance")/COUNTA('Controls Assessment'!F2:F100),0) -> 0.052631579
B41: Risk Management | C41: =COUNTIF('Controls Assessment'!R2:R100,"Risk Management") -> 3 | D41: =IFERROR(COUNTIF('Controls Assessment'!R2:R100,"Risk Management")/COUNTA('Controls Assessment'!F2:F100),0) -> 0.078947368
B42: Human Resources | C42: =COUNTIF('Controls Assessment'!R2:R100,"Human Resources") -> 2 | D42: =IFERROR(COUNTIF('Controls Assessment'!R2:R100,"Human Resources")/COUNTA('Controls Assessment'!F2:F100),0) -> 0.052631579
B43: Procurement and Vendor Management | C43: =COUNTIF('Controls Assessment'!R2:R100,"Procurement and Vendor Management") -> 1 | D43: =IFERROR(COUNTIF('Controls Assessment'!R2:R100,"Procurement and Vendor Management")/COUNTA('Controls Assessment'!F2:F100),0) -> 0.026315789
B44: Facilities and Physical Security | C44: =COUNTIF('Controls Assessment'!R2:R100,"Facilities and Physical Security") -> 1 | D44: =IFERROR(COUNTIF('Controls Assessment'!R2:R100,"Facilities and Physical Security")/COUNTA('Controls Assessment'!F2:F100),0) -> 0.026315789
B46: Panel 6 Action Status Heat Map
...

Sheet Assessment Detail Capture
AA1: License-ID: CN-NIST-CSF-SMB-20260522-001
B2: ASSESSMENT DETAIL CAPTURE
B3: NIST CSF 2.0 Small Business Cyber Risk Workplan
B4: Use this sheet to document multiple evidence items per metric. Enter the Metric Reference from Column F of the Controls Assessment to link each record. Add one row per evidence item.
B6: Column Guide
B7: Metric Reference | C7: Enter the Metric Reference from Column F of the Controls Assessment sheet (e.g. GV.OC-01-M1).
B8: Evidence Item No | C8: Sequential number per metric (1, 2, 3...). Add a new row for each additional evidence item.
B9: Evidence Type | C9: Select: Document / Interview / Observation / System Output / Configuration.
B10: Evidence Title | C10: Full name of the document, report, or source.
B11: Source Reference | C11: Version, date, URL, system identifier, or other locating reference.
B12: Provided By | C12: Name and role of the individual who provided or confirmed this evidence item.
B13: Date Received | C13: Date the evidence item was obtained or reviewed.
B14: Evidence Summary | C14: Summary of what this evidence item demonstrates in relation to the metric.
B15: Assessor Judgement | C15: How this evidence item informs the assessed score for this metric.
B16: Gaps or Caveats | C16: Any limitations, gaps, or caveats applicable to this evidence item.
B18: Metric Reference | C18: Evidence Item No | D18: Evidence Type | E18: Evidence Title | F18: Source Reference | G18: Provided By | H18: Date Received | I18: Evidence Summary | J18: Assessor Judgement | K18: Gaps or Caveats
B19: GV.OC-01-M1 | C19: 1
B20: GV.OC-03-M1 | C20: 1
B21: GV.RR-02-M1 | C21: 1
B22: GV.OC-04-M1 | C22: 1
B23: GV.RM-04-M1 | C23: 1
B24: GV.SC-06-M1 | C24: 1
B25: GV.RM-03-M1 | C25: 1
B26: GV.RR-01-M1 | C26: 1
B27: GV.PO-01-M1 | C27: 1
B28: ID.AM-01-M1 | C28: 1
B29: ID.RA-01-M1 | C29: 1
B30: ID.IM-01-M1 | C30: 1
... B56: RC.RP-06-M2 | C56: 1
B88: Cyber Native | cybernative.uk | Licensed under CC BY-NC-SA 4.0 | NIST CSF 2.0 Small Business Cyber Risk Workplan | 2026

Sheet Remediation Plan
AA1: License-ID: CN-NIST-CSF-SMB-20260522-001
B2: REMEDIATION PLAN
B3: NIST CSF 2.0 Small Business Cyber Risk Workplan
B4: Actions scoring Partial or Not Started appear as active remediation tasks. Actions scoring Implemented are automatically dimmed. Assign owners and target dates to build your remediation roadmap.
B6: Remediation Start Date | E6: =IFERROR(Cover!C13+14,"Enter Assessment Completion Date on Cover sheet") -> 14 | H6: Calculated automatically as 14 days after Assessment Completion Date on Cover sheet.
B8: Task Details | L8: Remediation Timeline (12 Weeks)
B9: Metric Ref | C9: Function | D9: Action | E9: Current Status | F9: Priority | G9: Owner | H9: Target Date | I9: Start Wk | J9: Duration | L9: Wk 1 | M9: Wk 2 | N9: Wk 3 | O9: Wk 4 | P9: Wk 5 | Q9: Wk 6 | R9: Wk 7 | S9: Wk 8 | T9: Wk 9 | U9: Wk 10 | V9: Wk 11 | W9: Wk 12
L10: 1 | M10: 2 | N10: 3 | O10: 4 | P10: 5 | Q10: 6 | R10: 7 | S10: 8 | T10: 9 | U10: 10 | V10: 11 | W10: 12
B11: ='Remediation Index'!B6 -> GV.OC-01-M1 | C11: ='Remediation Index'!C6 -> Govern | D11: ='Remediation Index'!D6 -> Mission and Cyber Risk Alignment | E11: ='Remediation Index'!E6 -> Not Assessed
B12: ='Remediation Index'!B7 -> GV.OC-03-M1 | C12: ='Remediation Index'!C7 -> Govern | D12: ='Remediation Index'!D7 -> Legal and Regulatory Requirements | E12: ='Remediation Index'!E7 -> Not Assessed
B13: ='Remediation Index'!B8 -> GV.RR-02-M1 | C13: ='Remediation Index'!C8 -> Govern | D13: ='Remediation Index'!D8 -> Cybersecurity Roles and Responsibilities | E13: ='Remediation Index'!E8 -> Not Assessed
B14: ='Remediation Index'!B9 -> GV.OC-04-M1 | C14: ='Remediation Index'!C9 -> Govern | D14: ='Remediation Index'!D9 -> Critical Asset Impact Assessment | E14: ='Remediation Index'!E9 -> Not Assessed
B15: ='Remediation Index'!B10 -> GV.RM-04-M1 | C15: ='Remediation Index'!C10 -> Govern | D15: ='Remediation Index'!D10 -> Cyber Insurance Evaluation | E15: ='Remediation Index'!E10 -> Not Assessed
B16: ='Remediation Index'!B11 -> GV.SC-06-M1 | C16: ='Remediation Index'!C11 -> Govern | D16: ='Remediation Index'!D11 -> Supplier Cyber Risk Due Diligence | E16: ='Remediation Index'!E11 -> Not Assessed
B17: ='Remediation Index'!B12 -> GV.RM-03-M1 | C17: ='Remediation Index'!C12 -> Govern | D17: ='Remediation Index'!D12 -> Enterprise Risk Integration | E17: ='Remediation Index'!E12 -> Not Assessed
B18: ='Remediation Index'!B13 -> GV.RR-01-M1 | C18: ='Remediation Index'!C13 -> Govern | D18: ='Remediation Index'!D13 -> Leadership Cybersecurity Culture | E18: ='Remediation Index'!E13 -> Not Assessed
B19: ='Remediation Index'!B14 -> GV.PO-01-M1 | C19: ='Remediation Index'!C14 -> Govern | D19: ='Remediation Index'!D14 -> Cybersecurity Policy | E19: ='Remediation Index'!E14 -> Not Assessed
B20: ='Remediation Index'!B15 -> ID.AM-01-M1 | C20: ='Remediation Index'!C15 -> Identify | D20: ='Remediation Index'!D15 -> Asset Inventory | E20: ='Remediation Index'!E15 -> Not Assessed
B21: ='Remediation Index'!B16 -> ID.RA-01-M1 | C21: ='Remediation Index'!C16 -> Identify | D21: ='Remediation Index'!D16 -> Vulnerability Identification | E21: ='Remediation Index'!E16 -> Not Assessed
B22: ='Remediation Index'!B17 -> ID.IM-01-M1 | C22: ='Remediation Index'!C17 -> Identify | D22: ='Remediation Index'!D17 -> Cybersecurity Program Effectiveness | E22: ='Remediation Index'!E17 -> Not Assessed
... B48: ='Remediation Index'!B43 -> RC.RP-06-M2 | C48: ='Remediation Index'!C43 -> Recover | D48: ='Remediation Index'!D43 -> Incident Closure and Resumption Declaration | E48: ='Remediation Index'!E43 -> Not Assessed
B50: Cyber Native | cybernative.uk | Licensed under CC BY-NC-SA 4.0 | NIST CSF 2.0 Small Business Cyber Risk Workplan | 2026

Sheet RAID Log
AA1: License-ID: CN-NIST-CSF-SMB-20260522-001
B2: RAID LOG
B3: NIST CSF 2.0 Small Business Cyber Risk Workplan
B4: Capture risks, assumptions, issues, and dependencies across the assessment program. Filter column B (Type) to work within a single category.
B6: RAID ID | C6: Type | D6: Category | E6: Title | F6: Description | G6: Date Raised | H6: Raised By | I6: Priority | J6: Probability | K6: Impact | L6: Score | M6: Owner | N6: Mitigation / Action | O6: Status | P6: Resolution Date | Q6: Notes
B7: R001 | C7: Risk | D7: Resource | E7: Key IT staff unavailable during assessment | F7: The individual or team responsible for IT operations may not be available throughout the assessment period, limiting access to evidence and system configuration data. | I7: High | J7: Medium | K7: High | L7: =IFERROR(IF(I7="High",3,IF(I7="Medium",2,1))*IF(J7="High",3,IF(J7="Medium",2,1)),"") -> 6 | M7: IT Manager | N7: Identify a deputy contact and brief them on evidence requirements before assessment commences. | O7: Open
B8: R002 | C8: Risk | D8: Technical | E8: Evidence for supplier assessments unavailable | F8: Supplier contracts and security questionnaire responses may not be readily accessible, impacting assessment of GV.SC-06 and related supply chain metrics. | I8: Medium | J8: Medium | K8: Medium | L8: =IFERROR(IF(I8="High",3,IF(I8="Medium",2,1))*IF(J8="High",3,IF(J8="Medium",2,1)),"") -> 4 | M8: Program Authority | N8: Request supplier documentation from procurement at least two weeks before fieldwork begins. | O8: Open
B9: A001 | C9: Assumption | D9: Program | E9: At least one named IT owner is available | F9: The assessment assumes that a named individual with IT operational knowledge is available to provide evidence and answer queries throughout the assessment period. | I9: Medium | K9: Medium | M9: Program Authority | N9: Confirm IT owner availability and obtain written commitment before assessment begins. | O9: Open
B10: A002 | C10: Assumption | D10: Technical | E10: Cloud services have been identified before assessment | F10: The assessment assumes that the organization has at least a working list of cloud platforms and SaaS applications in use, sufficient to complete the Business and Technology Context sheet. | I10: Low | K10: Low | M10: IT Manager | N10: Complete the Business and Technology Context sheet before opening the Controls Assessment. | O10: Open
B11: D001 | C11: Dependency | D11: Program | E11: Evidence gathering depends on multiple departments | F11: Assessment Detail Capture completion depends on evidence being gathered from IT Operations, Human Resources, Legal, Finance, and Leadership. Delays in any department will impact overall assessment progress. | I11: Medium | K11: Medium | M11: Program Authority | N11: Issue evidence request list to all responsible teams at program kick-off. | O11: Open
B12: D002 | C12: Dependency | D12: Resource | E12: Remediation resourcing depends on IT Operations availability | F12: The Remediation Plan assumes that IT Operations has sufficient capacity to execute remediation actions alongside business-as-usual activities. Capacity constraints will delay target dates. | I12: Medium | K12: Medium | M12: IT Manager | N12: Agree remediation capacity allocation with IT Operations before assigning target dates in the Remediation Plan. | O12: Open
B13: I001 | C13: Issue | D13: Program | E13: (Add issues as they arise during the assessment) | O13: Open
B25: Cyber Native | cybernative.uk | Licensed under CC BY-NC-SA 4.0 | NIST CSF 2.0 Small Business Cyber Risk Workplan | 2026

Sheet Risk Register
AA1: License-ID: CN-NIST-CSF-SMB-20260522-001
B2: RISK REGISTER
B3: NIST CSF 2.0 Small Business Cyber Risk Workplan
B4: Links assessment findings to enterprise risk language. Source Metric references Column F of the Controls Assessment sheet. Inherent Score and Residual Score are auto-calculated.
B6: Risk ID | C6: Source Metric | D6: Risk Title | E6: Risk Description | F6: Risk Category | G6: Likelihood (1-5) | H6: Impact (1-5) | I6: Inherent Score | J6: Existing Controls | K6: Residual Likelihood | L6: Residual Impact | M6: Residual Score | N6: Risk Owner | O6: Recommended Action | P6: Target Date | Q6: Status
B7: RR-001 | C7: GV.PO-01-M1 | D7: Absence of Formal Cybersecurity Policy | E7: Without a documented and enforced cybersecurity policy, staff behavior is ungoverned and the organization cannot demonstrate a baseline of security expectations to customers, insurers, or regulators. | F7: Compliance | G7: 3 | H7: 4 | I7: =IFERROR(G7*H7,"") -> 12 | J7: None identified. | K7: 2 | L7: 3 | M7: =IFERROR(K7*L7,"") -> 6 | N7: Program Authority | O7: Develop and publish a cybersecurity policy as a priority remediation action. Assign a named policy owner. | Q7: Open
B8: RR-002 | C8: PR.AA-03-M1 | D8: Accounts Compromised Due to Absence of MFA | E8: Without multi-factor authentication, business email and cloud service accounts are highly vulnerable to credential stuffing and phishing attacks, which remain the leading cause of SMB data breaches. | F8: Confidentiality | G8: 4 | H8: 5 | I8: =IFERROR(G8*H8,"") -> 20 | J8: Password policy in place. | K8: 2 | L8: 4 | M8: =IFERROR(K8*L8,"") -> 8 | N8: IT Manager | O8: Enable and enforce MFA on all accounts that support it as an immediate remediation priority. | Q8: Open
B9: RR-003 | C9: PR.DS-11-M1 | D9: Data Loss Due to Untested Backup Process | E9: If backup processes have not been tested, there is no assurance that data can be restored following ransomware, hardware failure, or accidental deletion. Recovery time may be materially longer than expected. | F9: Availability | G9: 3 | H9: 5 | I9: =IFERROR(G9*H9,"") -> 15 | J9: Backups scheduled daily. | K9: 2 | L9: 4 | M9: =IFERROR(K9*L9,"") -> 8 | N9: IT Manager | O9: Conduct a full restoration test and document the result. Schedule quarterly restoration tests going forward. | Q9: Open
B10: RR-004 | C10: RS.MA-01-M1 | D10: Uncoordinated Incident Response Causing Extended Downtime | E10: Without a documented and tested incident response plan, the business is likely to respond to a cybersecurity incident in an uncoordinated manner, extending downtime and increasing the risk of regulatory breach. | F10: Operational | G10: 3 | H10: 4 | I10: =IFERROR(G10*H10,"") -> 12 | J10: None identified. | K10: 2 | L10: 3 | M10: =IFERROR(K10*L10,"") -> 6 | N10: Program Authority | O10: Develop an incident response plan and conduct a tabletop exercise with key participants. | Q10: Open
B20: Cyber Native | cybernative.uk | Licensed under CC BY-NC-SA 4.0 | NIST CSF 2.0 Small Business Cyber Risk Workplan | 2026

Sheet Stakeholder Register
AA1: License-ID: CN-NIST-CSF-SMB-20260522-001
B2: STAKEHOLDER REGISTER
B3: NIST CSF 2.0 Small Business Cyber Risk Workplan
B4: Record all individuals and functions with a material interest in the assessment program. Use this register to plan engagement and ensure key contacts are captured in Column S of the Controls Assessment.
B6: Stakeholder ID | C6: Name | D6: Role and Title | E6: Organization / Dept | F6: Interest in Program | G6: Influence Level | H6: Engagement Approach | I6: Key Assessment Topics | J6: Last Engaged | K6: Next Action | L6: Notes
B7: SH001 | D7: Business Owner / CEO | E7: Leadership | F7: Overall program progress, regulatory exposure, cyber insurance implications, and resource decisions. | G7: High | H7: Lead | I7: GV.OC, GV.RM, GV.RR, GV.PO
B8: SH002 | D8: IT Manager or MSP Lead | E8: IT Operations | F8: Technical evidence provision across all Protect, Detect, and infrastructure-related metrics. | G8: High | H8: Collaborate | I8: PR.AA, PR.PS, PR.DS, DE.CM, RC.RP
B9: SH003 | D9: Finance / Accounting Lead | E9: Finance | F9: Access to financial systems evidence, payment card data scope, cyber insurance policy details. | G9: Medium | H9: Consult | I9: PR.DS, GV.RM-04, RS.CO
B10: SH004 | D10: HR / People Manager | E10: Human Resources | F10: Staff awareness training records, onboarding process documentation, leavers access revocation. | G10: Medium | H10: Consult | I10: PR.AT, PR.AA-01, ID.IM-04
B11: SH005 | D11: Legal / Compliance Lead | E11: Legal and Compliance | F11: Regulatory obligation register, notification requirements, contractual security clauses. | G11: High | H11: Collaborate | I11: GV.OC-03, RS.CO-02, RS.CO-03
B12: SH006 | D12: Procurement Lead | E12: Procurement | F12: Supplier contracts, vendor onboarding process, third-party access records. | G12: Medium | H12: Consult | I12: GV.SC-06
B20: Cyber Native | cybernative.uk | Licensed under CC BY-NC-SA 4.0 | NIST CSF 2.0 Small Business Cyber Risk Workplan | 2026

Sheet Remediation Index
AA1: License-ID: CN-NIST-CSF-SMB-20260522-001
B2: REMEDIATION INDEX -- Working Sheet. Do not edit any cell in this sheet directly.
B3: All values in this sheet are formula-driven from the Controls Assessment. This sheet drives the Visibility Flag used by the Remediation Plan to show or dim each action row. Editing cells here will break the Remediation Plan linkage.
B5: Metric Reference | C5: CSF Function | D5: Metric Name | E5: Status | F5: Responsible Team | G5: Show in Remediation Plan
B6: ='Controls Assessment'!F2 -> GV.OC-01-M1 | C6: ='Controls Assessment'!A2 -> Govern | D6: ='Controls Assessment'!G2 -> Mission and Cyber Risk Alignment | E6: ='Controls Assessment'!O2 -> Not Assessed | F6: ='Controls Assessment'!R2 -> Leadership and Ownership | G6: =IF(OR('Controls Assessment'!O2="PARTIAL",'Controls Assessment'!O2="FAIL",'Controls Assessment'!O2="Not Assessed"),"SHOW","COMPLETE") -> SHOW
B7: ='Controls Assessment'!F3 -> GV.OC-03-M1 | C7: ='Controls Assessment'!A3 -> Govern | D7: ='Controls Assessment'!G3 -> Legal and Regulatory Requirements | E7: ='Controls Assessment'!O3 -> Not Assessed | F7: ='Controls Assessment'!R3 -> Legal and Compliance | G7: =IF(OR('Controls Assessment'!O3="PARTIAL",'Controls Assessment'!O3="FAIL",'Controls Assessment'!O3="Not Assessed"),"SHOW","COMPLETE") -> SHOW
B8: ='Controls Assessment'!F4 -> GV.RR-02-M1 | C8: ='Controls Assessment'!A4 -> Govern | D8: ='Controls Assessment'!G4 -> Cybersecurity Roles and Responsibilities | E8: ='Controls Assessment'!O4 -> Not Assessed | F8: ='Controls Assessment'!R4 -> Leadership and Ownership | G8: =IF(OR('Controls Assessment'!O4="PARTIAL",'Controls Assessment'!O4="FAIL",'Controls Assessment'!O4="Not Assessed"),"SHOW","COMPLETE") -> SHOW
B9: ='Controls Assessment'!F5 -> GV.OC-04-M1 | C9: ='Controls Assessment'!A5 -> Govern | D9: ='Controls Assessment'!G5 -> Critical Asset Impact Assessment | E9: ='Controls Assessment'!O5 -> Not Assessed | F9: ='Controls Assessment'!R5 -> Leadership and Ownership | G9: =IF(OR('Controls Assessment'!O5="PARTIAL",'Controls Assessment'!O5="FAIL",'Controls Assessment'!O5="Not Assessed"),"SHOW","COMPLETE") -> SHOW
B10: ='Controls Assessment'!F6 -> GV.RM-04-M1 | C10: ='Controls Assessment'!A6 -> Govern | D10: ='Controls Assessment'!G6 -> Cyber Insurance Evaluation | E10: ='Controls Assessment'!O6 -> Not Assessed | F10: ='Controls Assessment'!R6 -> Leadership and Ownership | G10: =IF(OR('Controls Assessment'!O6="PARTIAL",'Controls Assessment'!O6="FAIL",'Controls Assessment'!O6="Not Assessed"),"SHOW","COMPLETE") -> SHOW
B11: ='Controls Assessment'!F7 -> GV.SC-06-M1 | C11: ='Controls Assessment'!A7 -> Govern | D11: ='Controls Assessment'!G7 -> Supplier Cyber Risk Due Diligence | E11: ='Controls Assessment'!O7 -> Not Assessed | F11: ='Controls Assessment'!R7 -> Procurement and Vendor Management | G11: =IF(OR('Controls Assessment'!O7="PARTIAL",'Controls Assessment'!O7="FAIL",'Controls Assessment'!O7="Not Assessed"),"SHOW","COMPLETE") -> SHOW
B12: ='Controls Assessment'!F8 -> GV.RM-03-M1 | C12: ='Controls Assessment'!A8 -> Govern | D12: ='Controls Assessment'!G8 -> Enterprise Risk Integration | E12: ='Controls Assessment'!O8 -> Not Assessed | F12: ='Controls Assessment'!R8 -> Risk Management | G12: =IF(OR('Controls Assessment'!O8="PARTIAL",'Controls Assessment'!O8="FAIL",'Controls Assessment'!O8="Not Assessed"),"SHOW","COMPLETE") -> SHOW
B13: ='Controls Assessment'!F9 -> GV.RR-01-M1 | C13: ='Controls Assessment'!A9 -> Govern | D13: ='Controls Assessment'!G9 -> Leadership Cybersecurity Culture | E13: ='Controls Assessment'!O9 -> Not Assessed | F13: ='Controls Assessment'!R9 -> Leadership and Ownership | G13: =IF(OR('Controls Assessment'!O9="PARTIAL",'Controls Assessment'!O9="FAIL",'Controls Assessment'!O9="Not Assessed"),"SHOW","COMPLETE") -> SHOW
B14: ='Controls Assessment'!F10 -> GV.PO-01-M1 | C14: ='Controls Assessment'!A10 -> Govern | D14: ='Controls Assessment'!G10 -> Cybersecurity Policy | E14: ='Controls Assessment'!O10 -> Not Assessed | F14: ='Controls Assessment'!R10 -> Leadership and Ownership | G14: =IF(OR('Controls Assessment'!O10="PARTIAL",'Controls Assessment'!O10="FAIL",'Controls Assessment'!O10="Not Assessed"),"SHOW","COMPLETE") -> SHOW
B15: ='Controls Assessment'!F11 -> ID.AM-01-M1 | C15: ='Controls Assessment'!A11 -> Identify | D15: ='Controls Assessment'!G11 -> Asset Inventory | E15: ='Controls Assessment'!O11 -> Not Assessed | F15: ='Controls Assessment'!R11 -> IT Operations | G15: =IF(OR('Controls Assessment'!O11="PARTIAL",'Controls Assessment'!O11="FAIL",'Controls Assessment'!O11="Not Assessed"),"SHOW","COMPLETE") -> SHOW
B16: ='Controls Assessment'!F12 -> ID.RA-01-M1 | C16: ='Controls Assessment'!A12 -> Identify | D16: ='Controls Assessment'!G12 -> Vulnerability Identification | E16: ='Controls Assessment'!O12 -> Not Assessed | F16: ='Controls Assessment'!R12 -> IT Operations | G16: =IF(OR('Controls Assessment'!O12="PARTIAL",'Controls Assessment'!O12="FAIL",'Controls Assessment'!O12="Not Assessed"),"SHOW","COMPLETE") -> SHOW
B17: ='Controls Assessment'!F13 -> ID.IM-01-M1 | C17: ='Controls Assessment'!A13 -> Identify | D17: ='Controls Assessment'!G13 -> Cybersecurity Program Effectiveness | E17: ='Controls Assessment'!O13 -> Not Assessed | F17: ='Controls Assessment'!R13 -> Risk Management | G17: =IF(OR('Controls Assessment'!O13="PARTIAL",'Controls Assessment'!O13="FAIL",'Controls Assessment'!O13="Not Assessed"),"SHOW","COMPLETE") -> SHOW
... B43: ='Controls Assessment'!F39 -> RC.RP-06-M2 | C43: ='Controls Assessment'!A39 -> Recover | D43: ='Controls Assessment'!G39 -> Incident Closure and Resumption Declaration | E43: ='Controls Assessment'!O39 -> Not Assessed | F43: ='Controls Assessment'!R39 -> Leadership and Ownership | G43: =IF(OR('Controls Assessment'!O39="PARTIAL",'Controls Assessment'!O39="FAIL",'Controls Assessment'!O39="Not Assessed"),"SHOW","COMPLETE") -> SHOW
B45: Cyber Native | cybernative.uk | Licensed under CC BY-NC-SA 4.0 | NIST CSF 2.0 Small Business Cyber Risk Workplan | 2026
